const User = require("../models/userModel");
const AppError = require("../utils/appError");
const catchAsync = require("../utils/catchAsync");

exports.getAllUsers = catchAsync(async (req, res, next) => {
  const users = await User.find();

  res.status(200).json({
    status: "success",
    results: users.length,
    users,
  });
  next();
});

exports.getUser = catchAsync(async (req, res, next) => {
  const user = await User.findById(req.params.id);

  if (!user) {
    return next(new AppError("That user does not exist.", 404));
  }

  res.status(200).json({
    status: "success",
    user,
  });
});

exports.createUser = catchAsync(async (req, res, next) => {
  const user = await User.create(req.body);

  res.status(201).json({
    status: "success",
    user,
  });
});

exports.updateUser = catchAsync(async (req, res, next) => {
  const user = await User.findByIdAndUpdate(req.params.id, req.body, {
    new: true,
    runValidators: true,
  });

  if (!user) {
    return next(new AppError("That user does not exist.", 404));
  }

  res.status(200).json({
    status: "success",
    user,
  });
});

exports.deleteUser = catchAsync(async (req, res, next) => {
  const user = await User.findByIdAndDelete(req.params.id);

  if (!user) {
    return next(new AppError("That user does not exist.", 404));
  }

  res.status(204).json({
    status: "success",
    user: null,
  });
});
